Workbook

Sheet Sheet1

Sheet Sheet3
S1: EXCESSO | T1: ARROZ | U1: FEIJAO | V1: MILHO | W1: TOTAL | AE1: =+V2+#REF! -> #REF!
E2: ARROZ | I2: FEIJAO | M2: MILHO | Q2: TOTAL | S2: SOFALA | T2: 0 | U2: 4935 | V2: 73762.5 | W2: 78697.5
B3: Column Labels
B4: Arroz | F4: Feijão | J4: Milho | N4: Total Sum of NOVA QUANTIDADE A ENTREGAR | O4: Total Sum of VAR VS PLAN ANTERIOR | P4: Total Sum of QUANTIDADE ENTREGUE | Q4: Total Sum of QUANTIDADE ENTREGUE +/-
A5: Row Labels | B5: Sum of NOVA QUANTIDADE A ENTREGAR | C5: Sum of VAR VS PLAN ANTERIOR | D5: Sum of QUANTIDADE ENTREGUE | E5: Sum of QUANTIDADE ENTREGUE +/- | F5: Sum of NOVA QUANTIDADE A ENTREGAR | G5: Sum of VAR VS PLAN ANTERIOR | H5: Sum of QUANTIDADE ENTREGUE | I5: Sum of QUANTIDADE ENTREGUE +/- | J5: Sum of NOVA QUANTIDADE A ENTREGAR | K5: Sum of VAR VS PLAN ANTERIOR | L5: Sum of QUANTIDADE ENTREGUE | M5: Sum of QUANTIDADE ENTREGUE +/-
A6: Gaza | B6: 437800 | C6: 0 | D6: 28800 | E6: -409000 | F6: 1131480 | G6: 0 | H6: 50565 | I6: -1080915 | J6: 833450 | K6: 0 | L6: 763809 | M6: -69641 | N6: 2402730 | O6: 0 | P6: 843174 | Q6: -1559556
A7: Manica | B7: 0 | C7: 0 | D7: 0 | E7: 0 | F7: 35850 | G7: -77460 | H7: 0 | I7: -35850 | J7: 29875 | K7: -64550 | L7: 2000 | M7: -27875 | N7: 65725 | O7: -142010 | P7: 2000 | Q7: -63725
A8: Maputo | B8: 98500 | C8: 0 | D8: 0 | E8: -98500 | F8: 268500 | G8: 0 | H8: 11490 | I8: -257010 | J8: 199125 | K8: 0 | L8: 172727 | M8: -26398 | N8: 566125 | O8: 0 | P8: 184217 | Q8: -381908
A9: Sofala | B9: 366550 | C9: -198800 | D9: 0 | E9: -366550 | F9: 317115 | G9: -260205 | H9: 62385 | I9: -254730 | J9: 214800 | K9: -124962.5 | L9: 185526 | M9: -29274 | N9: 898465 | O9: -583967.5 | P9: 247911 | Q9: -650554
A10: Beira | B10: 7500 | C10: -2300 | D10: 0 | E10: -7500 | F10: 2250 | G10: -690 | H10: 0 | I10: -2250 | N10: 9750 | O10: -2990 | P10: 0 | Q10: -9750
A11: Buzi | B11: 210500 | C11: -233300 | D11: 0 | E11: -210500 | F11: 104400 | G11: -109380 | H11: 9555 | I11: -94845 | J11: 65925 | K11: -1275 | L11: 59288 | M11: -6637 | N11: 380825 | O11: -343955 | P11: 68843 | Q11: -311982
A12: Caia | B12: 42650 | C12: -31300 | D12: 0 | E12: -42650 | F12: 34965 | G12: -8490 | H12: 30000 | I12: -4965 | J12: 18475 | K12: 750 | L12: 0 | M12: -18475 | N12: 96090 | O12: -39040 | P12: 30000 | Q12: -66090
A13: Chemba | B13: 4450 | C13: -32200 | D13: 0 | E13: -4450 | F13: 33570 | G13: -60735 | H13: 0 | I13: -33570 | J13: 26862.5 | K13: -42562.5 | L13: 29999 | M13: 3136.5 | N13: 64882.5 | O13: -135497.5 | P13: 29999 | Q13: -34883.5
A14: Chibabava | F14: 9885 | G14: 4035 | H14: 0 | I14: -9885 | J14: 8237.5 | K14: 3362.5 | L14: 0 | M14: -8237.5 | N14: 18122.5 | O14: 7397.5 | P14: 0 | Q14: -18122.5
A15: Dondo | B15: 19300 | C15: 19300 | D15: 0 | E15: -19300 | F15: 5790 | G15: -11625 | H15: 0 | I15: -5790 | J15: 0 | K15: -14512.5 | L15: 0 | M15: 0 | N15: 25090 | O15: -6837.5 | P15: 0 | Q15: -25090
A16: Gorongosa | B16: 0 | C16: 0 | D16: 0 | E16: 0 | F16: 14220 | G16: 8100 | H16: 5850 | I16: -8370 | J16: 11850 | K16: 6750 | L16: 5101 | M16: -6749 | N16: 26070 | O16: 14850 | P16: 10951 | Q16: -15119
A17: Machanga | B17: 4550 | C17: 4550 | D17: 0 | E17: -4550 | F17: 52335 | G17: -33120 | H17: 0 | I17: -52335 | J17: 42475 | K17: -28737.5 | L17: 35951 | M17: -6524 | N17: 99360 | O17: -57307.5 | P17: 35951 | Q17: -63409
A18: Marromeu | B18: 17600 | C18: 17600 | D18: 0 | E18: -17600 | F18: 7575 | G18: 180 | H18: 0 | I18: -7575 | J18: 1912.5 | K18: -4250 | L18: 0 | M18: -1912.5 | N18: 27087.5 | O18: 13530 | P18: 0 | Q18: -27087.5
A19: Muanza | B19: 25000 | C19: 25000 | D19: 0 | E19: -25000 | F19: 14685 | G19: -8760 | H19: 0 | I19: -14685 | J19: 5987.5 | K19: -13550 | L19: 0 | M19: -5987.5 | N19: 45672.5 | O19: 2690 | P19: 0 | Q19: -45672.5
A20: Nhamatanda | B20: 35000 | C20: 33850 | D20: 0 | E20: -35000 | F20: 37440 | G20: -39720 | H20: 16980 | I20: -20460 | J20: 33075 | K20: -30937.5 | L20: 55187 | M20: 22112 | N20: 105515 | O20: -36807.5 | P20: 72167 | Q20: -33348
A21: Tete | B21: 1000 | C21: -61900 | D21: 0 | E21: -1000 | F21: 58515 | G21: -51540 | H21: 0 | I21: -58515 | J21: 48512.5 | K21: -27475 | L21: 27451 | M21: -21061.5 | N21: 108027.5 | O21: -140915 | P21: 27451 | Q21: -80576.5
A22: Zambezia | B22: 84500 | C22: -124250 | D22: 0 | E22: -84500 | F22: 102180 | G22: -77520 | H22: 0 | I22: -102180 | J22: 64025 | K22: -33550 | L22: 0 | M22: -64025 | N22: 250705 | O22: -235320 | P22: 0 | Q22: -250705
A23: Grand Total | B23: 988350 | C23: -384950 | D23: 28800 | E23: -959550 | F23: 1913640 | G23: -466725 | H23: 124440 | I23: -1789200 | J23: 1389787.5 | K23: -250537.5 | L23: 1151513 | M23: -238274.5 | N23: 4291777.5 | O23: -1102212.5 | P23: 1304753 | Q23: -2987024.5
B26: 877700 | C26: -495600 | D26: 28800 | E26: -848900 | F26: 1823640 | G26: -556725 | H26: 124440 | I26: -1699200 | J26: 1300275 | K26: -340050 | L26: 1151513 | M26: -148752 | Q26: -2696862
B27: =+B23-B26 -> 110650 | C27: =+C23-C26 -> 110650 | D27: =+D23-D26 -> 0 | E27: =+E23-E26 -> -110650 | F27: =+F23-F26 -> 90000 | G27: =+G23-G26 -> 90000 | H27: =+H23-H26 -> 0 | I27: =+I23-I26 -> -90000 | ... P27: =+P23-P26 -> 1304753 | Q27: =+Q26-Q23 -> 290162.5

Sheet Planeamento Adicional
A1: Data | B1: Referencia | C1: codigo serviço | D1: Tipo | E1: Codigo Cliente | F1: Nº Volume novo | G1: Peso do Volume Kg | H1: NOVA QUANTIDADE A ENTREGAR | I1: VAR VS PLAN ANTERIOR | J1: Qtd kit1 | K1: Qtd kit2 | L1: Altura | M1: Largura | N1: Comprimento | O1: Nome Origem | P1: Morada Origem | Q1: Artigo | R1: Nº Fornecedor | S1: Cod Origem ( NUIT) | T1: Código Postal Origem | U1: Cod Destino ( NUIT) | V1: Nome Destino | W1: Morada Destino (Provincia) | X1: Distrito | Y1: Posto Administrativo | Z1: Localidade | AA1: Povoado | AB1: Local de Treinamento | AC1: Total de Kits por Povoado | AD1: Localidade Destino Destino | AE1: Código Postal Destino Destino | AF1: Nome do Extensionista | AG1: Num Contacto Destino (Contacto do extensionista) | AH1: Nome do Supervisor | AI1: Contacto do Supervisor | AJ1: Observações | AK1: CDT | AL1: Valor | AM1: Plano Facturaçao | AO1: Agregador | AP1: Proforma | AQ1: SDAE | AR1: Supervisor | AS1: custo unitario | AT1: Custo | AU1: preco unitario | AV1: Venda | AW1: Data de Recebimento | AX1: Data de Pagamento | AY1: Garantias | AZ1: Stock p/fornecer | BA1: Variação | BB1: Qtd Entregue (Finalizado) | BC1: Qtd Em Trânsito | BD1: Qtd Criado (ajustável) | BE1: QUANTIDADE ENTREGUE | BF1: QUANTIDADE ENTREGUE +/- | BG1: Estado Entrega | BH1: Extensionista Count | BL1: Qtd Actualizada | BM1: VAR | BN1: Extensionist_ID | BO1: Tipo de Feijão
A2: 46114 | B2: Feijão | F2: 75 | G2: 75 | H2: 0 | Q2: MXIXFEIJAOKG | U2: 2601050 | V2: Abdulcadre Antonio | W2: Zambezia | X2: A.Molocue | Y2: Chapala | AF2: Abdulcadre Antonio | AG2: 873020203 | AH2: Jacob Manuel | AI2: 865421928 | AM2: 260001 | BA2: -75 | BE2: =+BB2+BC2 -> 0 | BF2: =+BE2-H2 -> 0 | BG2: Sem registo | BH2: =+VLOOKUP(AF2,Sheet4!A:A,1,FALSE) -> #N/A | BL2: 0 | BM2: =+H2+-BL2 -> 0 | BN2: 0601-0001 | BO2: Vulgar
A3: 46114 | B3: Emamectin | F3: 5 | G3: 2.5 | H3: 0 | Q3: AGRIFEMMA01L | U3: 2601050 | V3: Abdulcadre Antonio | W3: Zambezia | X3: A.Molocue | Y3: Chapala | AF3: Abdulcadre Antonio | AG3: 873020203 | AH3: Jacob Manuel | AI3: 865421928 | AM3: 260001 | BA3: -5 | BE3: =+BB3+BC3 -> 0 | BF3: =+BE3-H3 -> 0 | BG3: Sem registo | BH3: =+VLOOKUP(AF3,Sheet4!A:A,1,FALSE) -> #N/A | BL3: 0 | BM3: =+H3+-BL3 -> 0 | BN3: 0601-0001
A4: 46114 | B4: Sacos Hermeticos | F4: 100 | G4: 100 | H4: 0 | Q4: SUSSACO | U4: 2601050 | V4: Abdulcadre Antonio | W4: Zambezia | X4: A.Molocue | Y4: Chapala | AF4: Abdulcadre Antonio | AG4: 873020203 | AH4: Jacob Manuel | AI4: 865421928 | AM4: 260001 | BA4: -100 | BE4: =+BB4+BC4 -> 0 | BF4: =+BE4-H4 -> 0 | BG4: Sem registo | BH4: =+VLOOKUP(AF4,Sheet4!A:A,1,FALSE) -> #N/A | BL4: 0 | BM4: =+H4+-BL4 -> 0 | BN4: 0601-0001
A5: 46114 | B5: Imadocloprid | F5: 4 | G5: 2 | H5: 0 | Q5: AGRIMIDACLORP1L | U5: 2601050 | V5: Abdulcadre Antonio | W5: Zambezia | X5: A.Molocue | Y5: Chapala | AF5: Abdulcadre Antonio | AG5: 873020203 | AH5: Jacob Manuel | AI5: 865421928 | AM5: 260001 | BA5: -4 | BE5: =+BB5+BC5 -> 0 | BF5: =+BE5-H5 -> 0 | BG5: Sem registo | BH5: =+VLOOKUP(AF5,Sheet4!A:A,1,FALSE) -> #N/A | BL5: 0 | BM5: =+H5+-BL5 -> 0 | BN5: 0601-0001
A6: 46114 | B6: Milho | F6: 50 | G6: 50 | H6: 0 | J6: =H6/12.5 -> 0 | Q6: MXIXMILHOKG | U6: 2601050 | V6: Abdulcadre Antonio | W6: Zambezia | X6: A.Molocue | Y6: Chapala | AF6: Abdulcadre Antonio | AG6: 873020203 | AH6: Jacob Manuel | AI6: 865421928 | AM6: 260001 | BA6: -50 | BE6: =+BB6+BC6 -> 0 | BF6: =+BE6-H6 -> 0 | BG6: Sem registo | BH6: =+VLOOKUP(AF6,Sheet4!A:A,1,FALSE) -> #N/A | BL6: 0 | BM6: =+H6+-BL6 -> 0 | BN6: 0601-0001
A7: 46114 | B7: MCPA | F7: 3 | G7: 1.5 | H7: 0 | Q7: AGRIMHMCPA1L | U7: 2601050 | V7: Abdulcadre Antonio | W7: Zambezia | X7: A.Molocue | Y7: Chapala | AF7: Abdulcadre Antonio | AG7: 873020203 | AH7: Jacob Manuel | AI7: 865421928 | AM7: 260001 | BA7: -3 | BE7: =+BB7+BC7 -> 0 | BF7: =+BE7-H7 -> 0 | BG7: Sem registo | BH7: =+VLOOKUP(AF7,Sheet4!A:A,1,FALSE) -> #N/A | BL7: 0 | BM7: =+H7+-BL7 -> 0 | BN7: 0601-0001
A8: 46114 | B8: Arroz | F8: 50 | G8: 50 | H8: 0 | I8: =H8-G8 -> -50 | K8: =H8/50 -> 0 | Q8: MXIXARROZKG | U8: 2601050 | V8: Abdulcadre Antonio | W8: Zambezia | X8: A.Molocue | Y8: Chapala | AF8: Abdulcadre Antonio | AG8: 873020203 | AH8: Jacob Manuel | AI8: 865421928 | AM8: 260001 | BA8: -50 | BE8: =+BB8+BC8 -> 0 | BF8: =+BE8-H8 -> 0 | BG8: Sem registo | BH8: =+VLOOKUP(AF8,Sheet4!A:A,1,FALSE) -> #N/A | BL8: 0 | BM8: =+H8+-BL8 -> 0 | BN8: 0601-0001
A9: 46114 | B9: Feijão | F9: 1425 | G9: 1425 | H9: 315 | I9: =H9-G9 -> -1110 | Q9: MXIXFEIJAOKG | U9: 2601051 | V9: Abiba Paiva Luís Lundo | W9: Zambezia | X9: CHINDE | Y9: MATILDE | AF9: Abiba Paiva Luís Lundo | AG9: 877471047/845258221 | AH9: Victor Carlos Duarte Soromenho | AI9: 848973362 / 874800380 | AM9: 260001 | BA9: -1110 | BE9: =+BB9+BC9 -> 0 | BF9: =+BE9-H9 -> -315 | BG9: Sem registo | BH9: =+VLOOKUP(AF9,Sheet4!A:A,1,FALSE) -> #N/A | BL9: 315 | BM9: =+H9+-BL9 -> 0 | BN9: 0602-0001 | BO9: Vulgar
A10: 46114 | B10: Emamectin | F10: 95 | G10: 47.5 | H10: 21 | I10: =H10-G10 -> -26.5 | Q10: AGRIFEMMA01L | U10: 2601051 | V10: Abiba Paiva Luís Lundo | W10: Zambezia | X10: CHINDE | Y10: MATILDE | AF10: Abiba Paiva Luís Lundo | AG10: 877471047/845258221 | AH10: Victor Carlos Duarte Soromenho | AI10: 848973362 / 874800380 | AM10: 260001 | BA10: -74 | BE10: =+BB10+BC10 -> 0 | BF10: =+BE10-H10 -> -21 | BG10: Sem registo | BH10: =+VLOOKUP(AF10,Sheet4!A:A,1,FALSE) -> #N/A | BL10: 21 | BM10: =+H10+-BL10 -> 0 | BN10: 0602-0001
A11: 46114 | B11: Sacos Hermeticos | F11: 1900 | G11: 1900 | H11: 420 | I11: =H11-G11 -> -1480 | Q11: SUSSACO | U11: 2601051 | V11: Abiba Paiva Luís Lundo | W11: Zambezia | X11: CHINDE | Y11: MATILDE | AF11: Abiba Paiva Luís Lundo | AG11: 877471047/845258221 | AH11: Victor Carlos Duarte Soromenho | AI11: 848973362 / 874800380 | AM11: 260001 | BA11: -1480 | BE11: =+BB11+BC11 -> 0 | BF11: =+BE11-H11 -> -420 | BG11: Sem registo | BH11: =+VLOOKUP(AF11,Sheet4!A:A,1,FALSE) -> #N/A | BL11: 420 | BM11: =+H11+-BL11 -> 0 | BN11: 0602-0001
A12: 46114 | B12: Imadocloprid | F12: 76 | G12: 38 | H12: 18 | I12: =H12-G12 -> -20 | Q12: AGRIMIDACLORP1L | U12: 2601051 | V12: Abiba Paiva Luís Lundo | W12: Zambezia | X12: CHINDE | Y12: MATILDE | AF12: Abiba Paiva Luís Lundo | AG12: 877471047/845258221 | AH12: Victor Carlos Duarte Soromenho | AI12: 848973362 / 874800380 | AM12: 260001 | BA12: -58 | BE12: =+BB12+BC12 -> 0 | BF12: =+BE12-H12 -> -18 | BG12: Sem registo | BH12: =+VLOOKUP(AF12,Sheet4!A:A,1,FALSE) -> #N/A | BL12: 18 | BM12: =+H12+-BL12 -> 0 | BN12: 0602-0001
A13: 46114 | B13: Milho | F13: 950 | G13: 950 | H13: 225 | I13: =H13-G13 -> -725 | J13: =H13/12.5 -> 18 | Q13: MXIXMILHOKG | U13: 2601051 | V13: Abiba Paiva Luís Lundo | W13: Zambezia | X13: CHINDE | Y13: MATILDE | AF13: Abiba Paiva Luís Lundo | AG13: 877471047/845258221 | AH13: Victor Carlos Duarte Soromenho | AI13: 848973362 / 874800380 | AM13: 260001 | BA13: -725 | BE13: =+BB13+BC13 -> 0 | BF13: =+BE13-H13 -> -225 | BG13: Sem registo | BH13: =+VLOOKUP(AF13,Sheet4!A:A,1,FALSE) -> #N/A | BL13: 225 | BM13: =+H13+-BL13 -> 0 | BN13: 0602-0001
A14: 46114 | B14: MCPA | F14: 57 | G14: 28.5 | H14: 9 | I14: =H14-G14 -> -19.5 | Q14: AGRIMHMCPA1L | U14: 2601051 | V14: Abiba Paiva Luís Lundo | W14: Zambezia | X14: CHINDE | Y14: MATILDE | AF14: Abiba Paiva Luís Lundo | AG14: 877471047/845258221 | AH14: Victor Carlos Duarte Soromenho | AI14: 848973362 / 874800380 | AM14: 260001 | BA14: -48 | BE14: =+BB14+BC14 -> 0 | BF14: =+BE14-H14 -> -9 | BG14: Sem registo | BH14: =+VLOOKUP(AF14,Sheet4!A:A,1,FALSE) -> #N/A | BL14: 9 | BM14: =+H14+-BL14 -> 0 | BN14: 0602-0001
A15: 46114 | B15: Arroz | F15: 950 | G15: 950 | H15: 150 | I15: =H15-G15 -> -800 | K15: =H15/50 -> 3 | Q15: MXIXARROZKG | U15: 2601051 | V15: Abiba Paiva Luís Lundo | W15: Zambezia | X15: CHINDE | Y15: MATILDE | AF15: Abiba Paiva Luís Lundo | AG15: 877471047/845258221 | AH15: Victor Carlos Duarte Soromenho | AI15: 848973362 / 874800380 | AM15: 260001 | BA15: -800 | BE15: =+BB15+BC15 -> 0 | BF15: =+BE15-H15 -> -150 | BG15: Sem registo | BH15: =+VLOOKUP(AF15,Sheet4!A:A,1,FALSE) -> #N/A | BL15: 150 | BM15: =+H15+-BL15 -> 0 | BN15: 0602-0001
A16: 46114 | B16: Feijão | F16: 315 | G16: 315 | H16: 255 | I16: -60 | Q16: MXIXFEIJAOKG | U16: 2601052 | V16: Abílio Vilanculos | W16: Maputo | X16: MANHIÇA | Y16: Associação agrícola de Malhalhana | AF16: Abílio Vilanculos | AG16: 852314121 | AH16: Joaquim Arnaldo Muchanga | AI16: 847870520 | AM16: 260001 | BC16: 315 | BE16: =+BB16+BC16 -> 315 | BF16: =+BE16-H16 -> 60 | BG16: Entregue | BH16: =+VLOOKUP(AF16,Sheet4!A:A,1,FALSE) -> #N/A | BL16: 315 | BM16: =+H16+-BL16 -> -60 | BN16: 0303-0001 | BO16: Nhemba
A17: 46114 | B17: Feijão | F17: 375 | G17: 375 | H17: 300 | I17: -75 | Q17: MXIXFEIJAOKG | U17: 2601052 | V17: Abílio Vilanculos | W17: Maputo | X17: MANHIÇA | Y17: Associação de Balucuene | AF17: Abílio Vilanculos | AG17: 852314121 | AH17: Joaquim Arnaldo Muchanga | AI17: 847870520 | AM17: 260001 | BC17: 375 | BE17: =+BB17+BC17 -> 375 | BF17: =+BE17-H17 -> 75 | BG17: Entregue | BH17: =+VLOOKUP(AF17,Sheet4!A:A,1,FALSE) -> #N/A | BL17: 375 | BM17: =+H17+-BL17 -> -75 | BN17: 0303-0001 | BO17: Nhemba
A18: 46114 | B18: Feijão | F18: 135 | G18: 135 | H18: 105 | I18: -30 | Q18: MXIXFEIJAOKG | U18: 2601052 | V18: Abílio Vilanculos | W18: Maputo | X18: MANHIÇA | Y18: Associação de Chibucutso | AF18: Abílio Vilanculos | AG18: 852314121 | AH18: Joaquim Arnaldo Muchanga | AI18: 847870520 | AM18: 260001 | BD18: 135 | BE18: =+BB18+BC18 -> 0 | BF18: =+BE18-H18 -> -105 | BG18: Sem registo | BH18: =+VLOOKUP(AF18,Sheet4!A:A,1,FALSE) -> #N/A | BL18: 135 | BM18: =+H18+-BL18 -> -30 | BN18: 0303-0001 | BO18: Nhemba
A19: 46114 | B19: Feijão | F19: 870 | G19: 870 | H19: 705 | I19: -165 | Q19: MXIXFEIJAOKG | U19: 2601052 | V19: Abílio Vilanculos | W19: Maputo | X19: MANHIÇA | Y19: Associação DE Chirindzene | AF19: Abílio Vilanculos | AG19: 852314121 | AH19: Joaquim Arnaldo Muchanga | AI19: 847870520 | AM19: 260001 | BD19: 870 | BE19: =+BB19+BC19 -> 0 | BF19: =+BE19-H19 -> -705 | BG19: Sem registo | BH19: =+VLOOKUP(AF19,Sheet4!A:A,1,FALSE) -> #N/A | BL19: 870 | BM19: =+H19+-BL19 -> -165 | BN19: 0303-0001 | BO19: Nhemba
A20: 46114 | B20: Feijão | F20: 7545 | G20: 7545 | H20: 6075 | I20: -1470 | Q20: MXIXFEIJAOKG | U20: 2601052 | V20: Abílio Vilanculos | W20: Maputo | X20: MANHIÇA | Y20: Chirindzene | AF20: Abílio Vilanculos | AG20: 852314121 | AH20: Joaquim Arnaldo Muchanga | AI20: 847870520 | AM20: 260001 | BD20: 7545 | BE20: =+BB20+BC20 -> 0 | BF20: =+BE20-H20 -> -6075 | BG20: Sem registo | BH20: =+VLOOKUP(AF20,Sheet4!A:A,1,FALSE) -> #N/A | BL20: 7545 | BM20: =+H20+-BL20 -> -1470 | BN20: 0303-0001 | BO20: Nhemba
A21: 46114 | B21: Feijão | F21: 15 | G21: 15 | H21: 15 | I21: 0 | Q21: MXIXFEIJAOKG | U21: 2601052 | V21: Abílio Vilanculos | W21: Maputo | X21: MANHIÇA | Y21: Manhica-sede | AF21: Abílio Vilanculos | AG21: 852314121 | AH21: Joaquim Arnaldo Muchanga | AI21: 847870520 | AM21: 260001 | BC21: 15 | BE21: =+BB21+BC21 -> 15 | BF21: =+BE21-H21 -> 0 | BG21: Entregue | BH21: =+VLOOKUP(AF21,Sheet4!A:A,1,FALSE) -> #N/A | BL21: 15 | BM21: =+H21+-BL21 -> 0 | BN21: 0303-0001 | BO21: Nhemba
A22: 46114 | B22: Feijão | F22: 1290 | G22: 1290 | H22: 1035 | I22: -255 | Q22: MXIXFEIJAOKG | U22: 2601052 | V22: Abílio Vilanculos | W22: Maputo | X22: MANHIÇA | Y22: Zona 2 | AF22: Abílio Vilanculos | AG22: 852314121 | AH22: Joaquim Arnaldo Muchanga | AI22: 847870520 | AM22: 260001 | BD22: 1290 | BE22: =+BB22+BC22 -> 0 | BF22: =+BE22-H22 -> -1035 | BG22: Sem registo | BH22: =+VLOOKUP(AF22,Sheet4!A:A,1,FALSE) -> #N/A | BL22: 1290 | BM22: =+H22+-BL22 -> -255 | BN22: 0303-0001 | BO22: Nhemba
A23: 46114 | B23: Feijão | F23: 1050 | G23: 1050 | H23: 855 | I23: -195 | Q23: MXIXFEIJAOKG | U23: 2601052 | V23: Abílio Vilanculos | W23: Maputo | X23: MANHIÇA | Y23: Zona 8 | AF23: Abílio Vilanculos | AG23: 852314121 | AH23: Joaquim Arnaldo Muchanga | AI23: 847870520 | AM23: 260001 | BD23: 1050 | BE23: =+BB23+BC23 -> 0 | BF23: =+BE23-H23 -> -855 | BG23: Sem registo | BH23: =+VLOOKUP(AF23,Sheet4!A:A,1,FALSE) -> #N/A | BL23: 1050 | BM23: =+H23+-BL23 -> -195 | BN23: 0303-0001 | BO23: Nhemba
A24: 46114 | B24: Emamectin | F24: 21 | G24: 10.5 | H24: 17 | I24: -4 | Q24: AGRIFEMMA01L | U24: 2601052 | V24: Abílio Vilanculos | W24: Maputo | X24: MANHIÇA | Y24: Associação agrícola de Malhalhana | AF24: Abílio Vilanculos | AG24: 852314121 | AH24: Joaquim Arnaldo Muchanga | AI24: 847870520 | AM24: 260001 | BE24: =+BB24+BC24 -> 0 | BF24: =+BE24-H24 -> -17 | BG24: Sem registo | BH24: =+VLOOKUP(AF24,Sheet4!A:A,1,FALSE) -> #N/A | BL24: 10.5 | BM24: =+H24+-BL24 -> 6.5 | BN24: 0303-0001
A25: 46114 | B25: Emamectin | F25: 25 | G25: 12.5 | H25: 20 | I25: -5 | Q25: AGRIFEMMA01L | U25: 2601052 | V25: Abílio Vilanculos | W25: Maputo | X25: MANHIÇA | Y25: Associação de Balucuene | AF25: Abílio Vilanculos | AG25: 852314121 | AH25: Joaquim Arnaldo Muchanga | AI25: 847870520 | AM25: 260001 | BE25: =+BB25+BC25 -> 0 | BF25: =+BE25-H25 -> -20 | BG25: Sem registo | BH25: =+VLOOKUP(AF25,Sheet4!A:A,1,FALSE) -> #N/A | BL25: 12.5 | BM25: =+H25+-BL25 -> 7.5 | BN25: 0303-0001
A26: 46114 | B26: Emamectin | F26: 9 | G26: 4.5 | H26: 7 | I26: -2 | Q26: AGRIFEMMA01L | U26: 2601052 | V26: Abílio Vilanculos | W26: Maputo | X26: MANHIÇA | Y26: Associação de Chibucutso | AF26: Abílio Vilanculos | AG26: 852314121 | AH26: Joaquim Arnaldo Muchanga | AI26: 847870520 | AM26: 260001 | BE26: =+BB26+BC26 -> 0 | BF26: =+BE26-H26 -> -7 | BG26: Sem registo | BH26: =+VLOOKUP(AF26,Sheet4!A:A,1,FALSE) -> #N/A | BL26: 4.5 | BM26: =+H26+-BL26 -> 2.5 | BN26: 0303-0001
A27: 46114 | B27: Emamectin | F27: 58 | G27: 29 | H27: 47 | I27: -11 | Q27: AGRIFEMMA01L | U27: 2601052 | V27: Abílio Vilanculos | W27: Maputo | X27: MANHIÇA | Y27: Associação DE Chirindzene | AF27: Abílio Vilanculos | AG27: 852314121 | AH27: Joaquim Arnaldo Muchanga | AI27: 847870520 | AM27: 260001 | BE27: =+BB27+BC27 -> 0 | BF27: =+BE27-H27 -> -47 | BG27: Sem registo | BH27: =+VLOOKUP(AF27,Sheet4!A:A,1,FALSE) -> #N/A | BL27: 29 | BM27: =+H27+-BL27 -> 18 | BN27: 0303-0001
A28: 46114 | B28: Emamectin | F28: 503 | G28: 251.5 | H28: 405 | I28: -98 | Q28: AGRIFEMMA01L | U28: 2601052 | V28: Abílio Vilanculos | W28: Maputo | X28: MANHIÇA | Y28: Chirindzene | AF28: Abílio Vilanculos | AG28: 852314121 | AH28: Joaquim Arnaldo Muchanga | AI28: 847870520 | AM28: 260001 | BE28: =+BB28+BC28 -> 0 | BF28: =+BE28-H28 -> -405 | BG28: Sem registo | BH28: =+VLOOKUP(AF28,Sheet4!A:A,1,FALSE) -> #N/A | BL28: 251.5 | BM28: =+H28+-BL28 -> 153.5 | BN28: 0303-0001
A29: 46114 | B29: Emamectin | F29: 1 | G29: 0.5 | H29: 1 | I29: 0 | Q29: AGRIFEMMA01L | U29: 2601052 | V29: Abílio Vilanculos | W29: Maputo | X29: MANHIÇA | Y29: Manhica-sede | AF29: Abílio Vilanculos | AG29: 852314121 | AH29: Joaquim Arnaldo Muchanga | AI29: 847870520 | AM29: 260001 | BE29: =+BB29+BC29 -> 0 | BF29: =+BE29-H29 -> -1 | BG29: Sem registo | BH29: =+VLOOKUP(AF29,Sheet4!A:A,1,FALSE) -> #N/A | BL29: 0.5 | BM29: =+H29+-BL29 -> 0.5 | BN29: 0303-0001
A30: 46114 | B30: Emamectin | F30: 86 | G30: 43 | H30: 69 | I30: -17 | Q30: AGRIFEMMA01L | U30: 2601052 | V30: Abílio Vilanculos | W30: Maputo | X30: MANHIÇA | Y30: Zona 2 | AF30: Abílio Vilanculos | AG30: 852314121 | AH30: Joaquim Arnaldo Muchanga | AI30: 847870520 | AM30: 260001 | BE30: =+BB30+BC30 -> 0 | BF30: =+BE30-H30 -> -69 | BG30: Sem registo | BH30: =+VLOOKUP(AF30,Sheet4!A:A,1,FALSE) -> #N/A | BL30: 43 | BM30: =+H30+-BL30 -> 26 | BN30: 0303-0001
A31: 46114 | B31: Emamectin | F31: 70 | G31: 35 | H31: 57 | I31: -13 | Q31: AGRIFEMMA01L | U31: 2601052 | V31: Abílio Vilanculos | W31: Maputo | X31: MANHIÇA | Y31: Zona 8 | AF31: Abílio Vilanculos | AG31: 852314121 | AH31: Joaquim Arnaldo Muchanga | AI31: 847870520 | AM31: 260001 | BE31: =+BB31+BC31 -> 0 | BF31: =+BE31-H31 -> -57 | BG31: Sem registo | BH31: =+VLOOKUP(AF31,Sheet4!A:A,1,FALSE) -> #N/A | BL31: 35 | BM31: =+H31+-BL31 -> 22 | BN31: 0303-0001
A32: 46114 | B32: Sacos Hermeticos | F32: 420 | G32: 420 | H32: 340 | I32: -80 | Q32: SUSSACO | U32: 2601052 | V32: Abílio Vilanculos | W32: Maputo | X32: MANHIÇA | Y32: Associação agrícola de Malhalhana | AF32: Abílio Vilanculos | AG32: 852314121 | AH32: Joaquim Arnaldo Muchanga | AI32: 847870520 | AM32: 260001 | BE32: =+BB32+BC32 -> 0 | BF32: =+BE32-H32 -> -340 | BG32: Sem registo | BH32: =+VLOOKUP(AF32,Sheet4!A:A,1,FALSE) -> #N/A | BL32: 420 | BM32: =+H32+-BL32 -> -80 | BN32: 0303-0001
A33: 46114 | B33: Sacos Hermeticos | F33: 500 | G33: 500 | H33: 400 | I33: -100 | Q33: SUSSACO | U33: 2601052 | V33: Abílio Vilanculos | W33: Maputo | X33: MANHIÇA | Y33: Associação de Balucuene | AF33: Abílio Vilanculos | AG33: 852314121 | AH33: Joaquim Arnaldo Muchanga | AI33: 847870520 | AM33: 260001 | BE33: =+BB33+BC33 -> 0 | BF33: =+BE33-H33 -> -400 | BG33: Sem registo | BH33: =+VLOOKUP(AF33,Sheet4!A:A,1,FALSE) -> #N/A | BL33: 500 | BM33: =+H33+-BL33 -> -100 | BN33: 0303-0001
A34: 46114 | B34: Sacos Hermeticos | F34: 180 | G34: 180 | H34: 140 | I34: -40 | Q34: SUSSACO | U34: 2601052 | V34: Abílio Vilanculos | W34: Maputo | X34: MANHIÇA | Y34: Associação de Chibucutso | AF34: Abílio Vilanculos | AG34: 852314121 | AH34: Joaquim Arnaldo Muchanga | AI34: 847870520 | AM34: 260001 | BE34: =+BB34+BC34 -> 0 | BF34: =+BE34-H34 -> -140 | BG34: Sem registo | BH34: =+VLOOKUP(AF34,Sheet4!A:A,1,FALSE) -> #N/A | BL34: 180 | BM34: =+H34+-BL34 -> -40 | BN34: 0303-0001
A35: 46114 | B35: Sacos Hermeticos | F35: 1160 | G35: 1160 | H35: 940 | I35: -220 | Q35: SUSSACO | U35: 2601052 | V35: Abílio Vilanculos | W35: Maputo | X35: MANHIÇA | Y35: Associação DE Chirindzene | AF35: Abílio Vilanculos | AG35: 852314121 | AH35: Joaquim Arnaldo Muchanga | AI35: 847870520 | AM35: 260001 | BE35: =+BB35+BC35 -> 0 | BF35: =+BE35-H35 -> -940 | BG35: Sem registo | BH35: =+VLOOKUP(AF35,Sheet4!A:A,1,FALSE) -> #N/A | BL35: 1160 | BM35: =+H35+-BL35 -> -220 | BN35: 0303-0001
... A47: 46114 | B47: Imadocloprid | F47: 70 | G47: 35 | H47: 57 | I47: -13 | Q47: AGRIMIDACLORP1L | U47: 2601052 | V47: Abílio Vilanculos | W47: Maputo | X47: MANHIÇA | Y47: Zona 8 | AF47: Abílio Vilanculos | AG47: 852314121 | AH47: Joaquim Arnaldo Muchanga | AI47: 847870520 | AM47: 260001 | BE47: =+BB47+BC47 -> 0 | BF47: =+BE47-H47 -> -57 | BG47: Sem registo | BH47: =+VLOOKUP(AF47,Sheet4!A:A,1,FALSE) -> #N/A | BL47: 35 | BM47: =+H47+-BL47 -> 22 | BN47: 0303-0001
A48: 46114 | B48: Milho | F48: 262.5 | G48: 262.5 | H48: 212.5 | I48: -50 | Q48: MXIXMILHOKG | U48: 2601052 | V48: Abílio Vilanculos | W48: Maputo | X48: MANHIÇA | Y48: Associação agrícola de Malhalhana | AF48: Abílio Vilanculos | AG48: 852314121 | AH48: Joaquim Arnaldo Muchanga | AI48: 847870520 | AM48: 260001 | BB48: 262 | BE48: =+BB48+BC48 -> 262 | BF48: =+BE48-H48 -> 49.5 | BG48: Entregue | BH48: =+VLOOKUP(AF48,Sheet4!A:A,1,FALSE) -> #N/A | BL48: 262.5 | BM48: =+H48+-BL48 -> -50 | BN48: 0303-0001
A49: 46114 | B49: Milho | F49: 312.5 | G49: 312.5 | H49: 250 | I49: -62.5 | Q49: MXIXMILHOKG | U49: 2601052 | V49: Abílio Vilanculos | W49: Maputo | X49: MANHIÇA | Y49: Associação de Balucuene | AF49: Abílio Vilanculos | AG49: 852314121 | AH49: Joaquim Arnaldo Muchanga | AI49: 847870520 | AM49: 260001 | BB49: 312 | BE49: =+BB49+BC49 -> 312 | BF49: =+BE49-H49 -> 62 | BG49: Entregue | BH49: =+VLOOKUP(AF49,Sheet4!A:A,1,FALSE) -> #N/A | BL49: 312.5 | BM49: =+H49+-BL49 -> -62.5 | BN49: 0303-0001
A50: 46114 | B50: Milho | F50: 112.5 | G50: 112.5 | H50: 87.5 | I50: -25 | Q50: MXIXMILHOKG | U50: 2601052 | V50: Abílio Vilanculos | W50: Maputo | X50: MANHIÇA | Y50: Associação de Chibucutso | AF50: Abílio Vilanculos | AG50: 852314121 | AH50: Joaquim Arnaldo Muchanga | AI50: 847870520 | AM50: 260001 | BB50: 112 | BE50: =+BB50+BC50 -> 112 | BF50: =+BE50-H50 -> 24.5 | BG50: Entregue | BH50: =+VLOOKUP(AF50,Sheet4!A:A,1,FALSE) -> #N/A | BL50: 112.5 | BM50: =+H50+-BL50 -> -25 | BN50: 0303-0001
A51: 46114 | B51: Milho | F51: 725 | G51: 725 | H51: 587.5 | I51: -137.5 | Q51: MXIXMILHOKG | U51: 2601052 | V51: Abílio Vilanculos | W51: Maputo | X51: MANHIÇA | Y51: Associação DE Chirindzene | AF51: Abílio Vilanculos | AG51: 852314121 | AH51: Joaquim Arnaldo Muchanga | AI51: 847870520 | AM51: 260001 | BB51: 725 | BE51: =+BB51+BC51 -> 725 | BF51: =+BE51-H51 -> 137.5 | BG51: Entregue | BH51: =+VLOOKUP(AF51,Sheet4!A:A,1,FALSE) -> #N/A | BL51: 725 | BM51: =+H51+-BL51 -> -137.5 | BN51: 0303-0001
...

Sheet Sheet4
A1: Berto Macino Chicico
A2: Carlos Roque Quembo
A3: Denilson Manuel Couve
A4: Denilson Manuel Couve
A5: Elisa Sarifo Sunzumua
A6: Elton Vasco Luisse
A7: Filipe Paulino Saute
A8: Helder Zunguze
A9: Helio Joao Manidide Sigauque
A10: Isaak Castrim Jossefa
A11: Isaquiel A. C. Meque
A12: Issa Pedro Aguiar
... A27: Zito Mario Abage

Sheet Totais por Província
A1: Província | B1: Antes (Planificado) | E1: Depois (Actualizado) | H1: Variação
A2: Província | B2: Kit 1 | C2: Kit 2 | D2: Total | E2: Kit 1 | F2: Kit 2 | G2: Total | H2: Kit 1 | I2: Kit 2 | J2: Total
A3: Maputo | B3: 15930 | C3: 1970 | D3: =B3+C3 -> 17900 | E3: sem dados | F3: sem dados | G3: sem dados | H3: sem dados | I3: sem dados | J3: sem dados
A4: Gaza | B4: 66676 | C4: 8756 | D4: =B4+C4 -> 75432 | E4: sem dados | F4: sem dados | G4: sem dados | H4: sem dados | I4: sem dados | J4: sem dados
A5: Sofala | B5: 27181 | C5: 11307 | D5: =B5+C5 -> 38488 | E5: 12194 | F5: 5201 | G5: =E5+F5 -> 17395 | H5: =E5-B5 -> -14987 | I5: =F5-C5 -> -6106 | J5: =G5-D5 -> -21093
A6: Zambezia | B6: 7810 | C6: 4175 | D6: =B6+C6 -> 11985 | E6: 3676 | F6: 1607 | G6: =E6+F6 -> 5283 | H6: =E6-B6 -> -4134 | I6: =F6-C6 -> -2568 | J6: =G6-D6 -> -6702
A7: Manica | B7: 7554 | C7: 0 | D7: =B7+C7 -> 7554 | E7: 2230 | F7: 0 | G7: =E7+F7 -> 2230 | H7: =E7-B7 -> -5324 | I7: =F7-C7 -> 0 | J7: =G7-D7 -> -5324
A8: Tete | B8: 6079 | C8: 1258 | D8: =B8+C8 -> 7337 | E8: 3316 | F8: 20 | G8: =E8+F8 -> 3336 | H8: =E8-B8 -> -2763 | I8: =F8-C8 -> -1238 | J8: =G8-D8 -> -4001
A9: TOTAL GERAL | B9: =SUM(B3:B8) -> 131230 | C9: =SUM(C3:C8) -> 27466 | D9: =SUM(D3:D8) -> 158696 | E9: =SUM(E3:E8) -> 21416 | F9: =SUM(F3:F8) -> 6828 | G9: =SUM(G3:G8) -> 28244 | H9: =SUM(H3:H8) -> -27208 | I9: =SUM(I3:I8) -> -9912 | J9: =SUM(J3:J8) -> -37120
A11: Notas:
A12: • 'Depois' inclui novos extensionistas inseridos pelas equipas provinciais (ver 'Novos Beneficiários').
A13: • Maputo e Gaza ainda sem listas actualizadas.

Sheet Necessidades por Província
A1: Necessidades de Insumos por Província
A3: Província | B3: Antes | E3: Depois
A4: Província | B4: Kit 1 | C4: Kit 2 | D4: Total | E4: Kit 1 | F4: Kit 2 | G4: Total
A5: Maputo | B5: 15930 | C5: 1970 | D5: =B5+C5 -> 17900 | E5: sem dados | F5: sem dados | G5: sem dados
A6: Gaza | B6: 66676 | C6: 8756 | D6: =B6+C6 -> 75432 | E6: sem dados | F6: sem dados | G6: sem dados
A7: Sofala | B7: 27181 | C7: 11307 | D7: =B7+C7 -> 38488 | E7: 12194 | F7: 5201 | G7: =E7+F7 -> 17395
A8: Zambezia | B8: 7810 | C8: 4175 | D8: =B8+C8 -> 11985 | E8: 3676 | F8: 1607 | G8: =E8+F8 -> 5283
A9: Manica | B9: 7554 | C9: 0 | D9: =B9+C9 -> 7554 | E9: 2230 | F9: 0 | G9: =E9+F9 -> 2230
A10: Tete | B10: 6079 | C10: 1258 | D10: =B10+C10 -> 7337 | E10: 3316 | F10: 20 | G10: =E10+F10 -> 3336
A11: TOTAL | B11: =SUM(B5:B10) -> 131230 | C11: =SUM(C5:C10) -> 27466 | D11: =SUM(D5:D10) -> 158696 | E11: =SUM(E5:E10) -> 21416 | F11: =SUM(F5:F10) -> 6828 | G11: =SUM(G5:G10) -> 28244
A14: Necessidades totais de insumos
A15: Insumo | B15: Unidade | C15: Maputo | F15: Gaza | I15: Sofala | L15: Zambezia | O15: Manica | R15: Tete | U15: TOTAL
C16: Antes | D16: Depois | E16: Variação | F16: Antes | G16: Depois | H16: Variação | I16: Antes | J16: Depois | K16: Variação | L16: Antes | M16: Depois | N16: Variação | O16: Antes | P16: Depois | Q16: Variação | R16: Antes | S16: Depois | T16: Variação | U16: Antes | V16: Depois | W16: Variação
A17: Milho | B17: Kg | C17: =IFERROR(B5*'Composição dos Kits'!C4+C5*'Composição dos Kits'!D4,0) -> 199125 | F17: =IFERROR(B6*'Composição dos Kits'!C4+C6*'Composição dos Kits'!D4,0) -> 833450 | I17: =IFERROR(B7*'Composição dos Kits'!C4+C7*'Composição dos Kits'!D4,0) -> 339762.5 | J17: =IFERROR(E7*'Composição dos Kits'!C4+F7*'Composição dos Kits'!D4,0) -> 152425 | K17: =J17-I17 -> -187337.5 | L17: =IFERROR(B8*'Composição dos Kits'!C4+C8*'Composição dos Kits'!D4,0) -> 97625 | M17: =IFERROR(E8*'Composição dos Kits'!C4+F8*'Composição dos Kits'!D4,0) -> 45950 | N17: =M17-L17 -> -51675 | O17: =IFERROR(B9*'Composição dos Kits'!C4+C9*'Composição dos Kits'!D4,0) -> 94425 | P17: =IFERROR(E9*'Composição dos Kits'!C4+F9*'Composição dos Kits'!D4,0) -> 27875 | Q17: =P17-O17 -> -66550 | R17: =IFERROR(B10*'Composição dos Kits'!C4+C10*'Composição dos Kits'!D4,0) -> 75987.5 | S17: =IFERROR(E10*'Composição dos Kits'!C4+F10*'Composição dos Kits'!D4,0) -> 41450 | T17: =S17-R17 -> -34537.5 | U17: =C17+F17+I17+L17+O17+R17 -> 1640375 | V17: =SUM(D17,G17,J17,M17,P17,S17) -> 267700 | W17: =V17-U17 -> -1372675
A18: Arroz | B18: Kg | C18: =IFERROR(B5*'Composição dos Kits'!C5+C5*'Composição dos Kits'!D5,0) -> 98500 | F18: =IFERROR(B6*'Composição dos Kits'!C5+C6*'Composição dos Kits'!D5,0) -> 437800 | I18: =IFERROR(B7*'Composição dos Kits'!C5+C7*'Composição dos Kits'!D5,0) -> 565350 | J18: =IFERROR(E7*'Composição dos Kits'!C5+F7*'Composição dos Kits'!D5,0) -> 260050 | K18: =J18-I18 -> -305300 | L18: =IFERROR(B8*'Composição dos Kits'!C5+C8*'Composição dos Kits'!D5,0) -> 208750 | M18: =IFERROR(E8*'Composição dos Kits'!C5+F8*'Composição dos Kits'!D5,0) -> 80350 | N18: =M18-L18 -> -128400 | O18: =IFERROR(B9*'Composição dos Kits'!C5+C9*'Composição dos Kits'!D5,0) -> 0 | P18: =IFERROR(E9*'Composição dos Kits'!C5+F9*'Composição dos Kits'!D5,0) -> 0 | Q18: =P18-O18 -> 0 | R18: =IFERROR(B10*'Composição dos Kits'!C5+C10*'Composição dos Kits'!D5,0) -> 62900 | S18: =IFERROR(E10*'Composição dos Kits'!C5+F10*'Composição dos Kits'!D5,0) -> 1000 | T18: =S18-R18 -> -61900 | U18: =C18+F18+I18+L18+O18+R18 -> 1373300 | V18: =SUM(D18,G18,J18,M18,P18,S18) -> 341400 | W18: =V18-U18 -> -1031900
A19: Feijão Vulgar | B19: Kg | C19: =IFERROR(B5*'Composição dos Kits'!C6+C5*'Composição dos Kits'!D6,0) -> 268500 | F19: =IFERROR(B6*'Composição dos Kits'!C6+C6*'Composição dos Kits'!D6,0) -> 1131480 | I19: =IFERROR(B7*'Composição dos Kits'!C6+C7*'Composição dos Kits'!D6,0) -> 577320 | J19: =IFERROR(E7*'Composição dos Kits'!C6+F7*'Composição dos Kits'!D6,0) -> 260925 | K19: =J19-I19 -> -316395 | L19: =IFERROR(B8*'Composição dos Kits'!C6+C8*'Composição dos Kits'!D6,0) -> 179775 | M19: =IFERROR(E8*'Composição dos Kits'!C6+F8*'Composição dos Kits'!D6,0) -> 79245 | N19: =M19-L19 -> -100530 | O19: =IFERROR(B9*'Composição dos Kits'!C6+C9*'Composição dos Kits'!D6,0) -> 113310 | P19: =IFERROR(E9*'Composição dos Kits'!C6+F9*'Composição dos Kits'!D6,0) -> 33450 | Q19: =P19-O19 -> -79860 | R19: =IFERROR(B10*'Composição dos Kits'!C6+C10*'Composição dos Kits'!D6,0) -> 110055 | S19: =IFERROR(E10*'Composição dos Kits'!C6+F10*'Composição dos Kits'!D6,0) -> 50040 | T19: =S19-R19 -> -60015 | U19: =C19+F19+I19+L19+O19+R19 -> 2380440 | V19: =SUM(D19,G19,J19,M19,P19,S19) -> 423660 | W19: =V19-U19 -> -1956780
A20: Couve | B20: g | C20: =IFERROR(B5*'Composição dos Kits'!C7+C5*'Composição dos Kits'!D7,0) -> 179000 | F20: =IFERROR(B6*'Composição dos Kits'!C7+C6*'Composição dos Kits'!D7,0) -> 754320 | I20: =IFERROR(B7*'Composição dos Kits'!C7+C7*'Composição dos Kits'!D7,0) -> 384880 | J20: =IFERROR(E7*'Composição dos Kits'!C7+F7*'Composição dos Kits'!D7,0) -> 173950 | K20: =J20-I20 -> -210930 | L20: =IFERROR(B8*'Composição dos Kits'!C7+C8*'Composição dos Kits'!D7,0) -> 119850 | M20: =IFERROR(E8*'Composição dos Kits'!C7+F8*'Composição dos Kits'!D7,0) -> 52830 | N20: =M20-L20 -> -67020 | O20: =IFERROR(B9*'Composição dos Kits'!C7+C9*'Composição dos Kits'!D7,0) -> 75540 | P20: =IFERROR(E9*'Composição dos Kits'!C7+F9*'Composição dos Kits'!D7,0) -> 22300 | Q20: =P20-O20 -> -53240 | R20: =IFERROR(B10*'Composição dos Kits'!C7+C10*'Composição dos Kits'!D7,0) -> 73370 | S20: =IFERROR(E10*'Composição dos Kits'!C7+F10*'Composição dos Kits'!D7,0) -> 33360 | T20: =S20-R20 -> -40010 | U20: =C20+F20+I20+L20+O20+R20 -> 1586960 | V20: =SUM(D20,G20,J20,M20,P20,S20) -> 282440 | W20: =V20-U20 -> -1304520
A21: Alface | B21: g | C21: =IFERROR(B5*'Composição dos Kits'!C8+C5*'Composição dos Kits'!D8,0) -> 179000 | F21: =IFERROR(B6*'Composição dos Kits'!C8+C6*'Composição dos Kits'!D8,0) -> 754320 | I21: =IFERROR(B7*'Composição dos Kits'!C8+C7*'Composição dos Kits'!D8,0) -> 384880 | J21: =IFERROR(E7*'Composição dos Kits'!C8+F7*'Composição dos Kits'!D8,0) -> 173950 | K21: =J21-I21 -> -210930 | L21: =IFERROR(B8*'Composição dos Kits'!C8+C8*'Composição dos Kits'!D8,0) -> 119850 | M21: =IFERROR(E8*'Composição dos Kits'!C8+F8*'Composição dos Kits'!D8,0) -> 52830 | N21: =M21-L21 -> -67020 | O21: =IFERROR(B9*'Composição dos Kits'!C8+C9*'Composição dos Kits'!D8,0) -> 75540 | P21: =IFERROR(E9*'Composição dos Kits'!C8+F9*'Composição dos Kits'!D8,0) -> 22300 | Q21: =P21-O21 -> -53240 | R21: =IFERROR(B10*'Composição dos Kits'!C8+C10*'Composição dos Kits'!D8,0) -> 73370 | S21: =IFERROR(E10*'Composição dos Kits'!C8+F10*'Composição dos Kits'!D8,0) -> 33360 | T21: =S21-R21 -> -40010 | U21: =C21+F21+I21+L21+O21+R21 -> 1586960 | V21: =SUM(D21,G21,J21,M21,P21,S21) -> 282440 | W21: =V21-U21 -> -1304520
A22: NPK 12.24.12 | B22: Kg | C22: =IFERROR(B5*'Composição dos Kits'!C9+C5*'Composição dos Kits'!D9,0) -> 895000 | F22: =IFERROR(B6*'Composição dos Kits'!C9+C6*'Composição dos Kits'!D9,0) -> 3771600 | I22: =IFERROR(B7*'Composição dos Kits'!C9+C7*'Composição dos Kits'!D9,0) -> 1924400 | J22: =IFERROR(E7*'Composição dos Kits'!C9+F7*'Composição dos Kits'!D9,0) -> 869750 | K22: =J22-I22 -> -1054650 | L22: =IFERROR(B8*'Composição dos Kits'!C9+C8*'Composição dos Kits'!D9,0) -> 599250 | M22: =IFERROR(E8*'Composição dos Kits'!C9+F8*'Composição dos Kits'!D9,0) -> 264150 | N22: =M22-L22 -> -335100 | O22: =IFERROR(B9*'Composição dos Kits'!C9+C9*'Composição dos Kits'!D9,0) -> 377700 | P22: =IFERROR(E9*'Composição dos Kits'!C9+F9*'Composição dos Kits'!D9,0) -> 111500 | Q22: =P22-O22 -> -266200 | R22: =IFERROR(B10*'Composição dos Kits'!C9+C10*'Composição dos Kits'!D9,0) -> 366850 | S22: =IFERROR(E10*'Composição dos Kits'!C9+F10*'Composição dos Kits'!D9,0) -> 166800 | T22: =S22-R22 -> -200050 | U22: =C22+F22+I22+L22+O22+R22 -> 7934800 | V22: =SUM(D22,G22,J22,M22,P22,S22) -> 1412200 | W22: =V22-U22 -> -6522600
A23: Enxada | B23: un | C23: =IFERROR(B5*'Composição dos Kits'!C10+C5*'Composição dos Kits'!D10,0) -> 17900 | F23: =IFERROR(B6*'Composição dos Kits'!C10+C6*'Composição dos Kits'!D10,0) -> 75432 | I23: =IFERROR(B7*'Composição dos Kits'!C10+C7*'Composição dos Kits'!D10,0) -> 38488 | J23: =IFERROR(E7*'Composição dos Kits'!C10+F7*'Composição dos Kits'!D10,0) -> 17395 | K23: =J23-I23 -> -21093 | L23: =IFERROR(B8*'Composição dos Kits'!C10+C8*'Composição dos Kits'!D10,0) -> 11985 | M23: =IFERROR(E8*'Composição dos Kits'!C10+F8*'Composição dos Kits'!D10,0) -> 5283 | N23: =M23-L23 -> -6702 | O23: =IFERROR(B9*'Composição dos Kits'!C10+C9*'Composição dos Kits'!D10,0) -> 7554 | P23: =IFERROR(E9*'Composição dos Kits'!C10+F9*'Composição dos Kits'!D10,0) -> 2230 | Q23: =P23-O23 -> -5324 | R23: =IFERROR(B10*'Composição dos Kits'!C10+C10*'Composição dos Kits'!D10,0) -> 7337 | S23: =IFERROR(E10*'Composição dos Kits'!C10+F10*'Composição dos Kits'!D10,0) -> 3336 | T23: =S23-R23 -> -4001 | U23: =C23+F23+I23+L23+O23+R23 -> 158696 | V23: =SUM(D23,G23,J23,M23,P23,S23) -> 28244 | W23: =V23-U23 -> -130452
A24: Emamectim Benzoato | B24: L | C24: =IFERROR(B5*'Composição dos Kits'!C11+C5*'Composição dos Kits'!D11,0) -> 8950 | F24: =IFERROR(B6*'Composição dos Kits'!C11+C6*'Composição dos Kits'!D11,0) -> 37716 | I24: =IFERROR(B7*'Composição dos Kits'!C11+C7*'Composição dos Kits'!D11,0) -> 19244 | J24: =IFERROR(E7*'Composição dos Kits'!C11+F7*'Composição dos Kits'!D11,0) -> 8697.5 | K24: =J24-I24 -> -10546.5 | L24: =IFERROR(B8*'Composição dos Kits'!C11+C8*'Composição dos Kits'!D11,0) -> 5992.5 | M24: =IFERROR(E8*'Composição dos Kits'!C11+F8*'Composição dos Kits'!D11,0) -> 2641.5 | N24: =M24-L24 -> -3351 | O24: =IFERROR(B9*'Composição dos Kits'!C11+C9*'Composição dos Kits'!D11,0) -> 3777 | P24: =IFERROR(E9*'Composição dos Kits'!C11+F9*'Composição dos Kits'!D11,0) -> 1115 | Q24: =P24-O24 -> -2662 | R24: =IFERROR(B10*'Composição dos Kits'!C11+C10*'Composição dos Kits'!D11,0) -> 3668.5 | S24: =IFERROR(E10*'Composição dos Kits'!C11+F10*'Composição dos Kits'!D11,0) -> 1668 | T24: =S24-R24 -> -2000.5 | U24: =C24+F24+I24+L24+O24+R24 -> 79348 | V24: =SUM(D24,G24,J24,M24,P24,S24) -> 14122 | W24: =V24-U24 -> -65226
A25: Imidacloprid | B25: L | C25: =IFERROR(B5*'Composição dos Kits'!C12+C5*'Composição dos Kits'!D12,0) -> 7965 | F25: =IFERROR(B6*'Composição dos Kits'!C12+C6*'Composição dos Kits'!D12,0) -> 33338 | I25: =IFERROR(B7*'Composição dos Kits'!C12+C7*'Composição dos Kits'!D12,0) -> 13590.5 | J25: =IFERROR(E7*'Composição dos Kits'!C12+F7*'Composição dos Kits'!D12,0) -> 6097 | K25: =J25-I25 -> -7493.5 | L25: =IFERROR(B8*'Composição dos Kits'!C12+C8*'Composição dos Kits'!D12,0) -> 3905 | M25: =IFERROR(E8*'Composição dos Kits'!C12+F8*'Composição dos Kits'!D12,0) -> 1838 | N25: =M25-L25 -> -2067 | O25: =IFERROR(B9*'Composição dos Kits'!C12+C9*'Composição dos Kits'!D12,0) -> 3777 | P25: =IFERROR(E9*'Composição dos Kits'!C12+F9*'Composição dos Kits'!D12,0) -> 1115 | Q25: =P25-O25 -> -2662 | R25: =IFERROR(B10*'Composição dos Kits'!C12+C10*'Composição dos Kits'!D12,0) -> 3039.5 | S25: =IFERROR(E10*'Composição dos Kits'!C12+F10*'Composição dos Kits'!D12,0) -> 1658 | T25: =S25-R25 -> -1381.5 | U25: =C25+F25+I25+L25+O25+R25 -> 65615 | V25: =SUM(D25,G25,J25,M25,P25,S25) -> 10708 | W25: =V25-U25 -> -54907
A26: MCPA | B26: L | C26: =IFERROR(B5*'Composição dos Kits'!C13+C5*'Composição dos Kits'!D13,0) -> 2955 | F26: =IFERROR(B6*'Composição dos Kits'!C13+C6*'Composição dos Kits'!D13,0) -> 13134 | I26: =IFERROR(B7*'Composição dos Kits'!C13+C7*'Composição dos Kits'!D13,0) -> 16960.5 | J26: =IFERROR(E7*'Composição dos Kits'!C13+F7*'Composição dos Kits'!D13,0) -> 7801.5 | K26: =J26-I26 -> -9159 | L26: =IFERROR(B8*'Composição dos Kits'!C13+C8*'Composição dos Kits'!D13,0) -> 6262.5 | M26: =IFERROR(E8*'Composição dos Kits'!C13+F8*'Composição dos Kits'!D13,0) -> 2410.5 | N26: =M26-L26 -> -3852 | O26: =IFERROR(B9*'Composição dos Kits'!C13+C9*'Composição dos Kits'!D13,0) -> 0 | P26: =IFERROR(E9*'Composição dos Kits'!C13+F9*'Composição dos Kits'!D13,0) -> 0 | Q26: =P26-O26 -> 0 | R26: =IFERROR(B10*'Composição dos Kits'!C13+C10*'Composição dos Kits'!D13,0) -> 1887 | S26: =IFERROR(E10*'Composição dos Kits'!C13+F10*'Composição dos Kits'!D13,0) -> 30 | T26: =S26-R26 -> -1857 | U26: =C26+F26+I26+L26+O26+R26 -> 41199 | V26: =SUM(D26,G26,J26,M26,P26,S26) -> 10242 | W26: =V26-U26 -> -30957

Sheet Novos Beneficiários
A1: Extensionist ID | B1: Extensionista | C1: Contacto Extensionista | D1: Supervisor | E1: Contacto Supervisor | F1: Província | G1: Distrito | H1: Localidade | I1: Kit | J1: Qtd Anterior | K1: Qtd Actualizada | L1: Variação
A2: 0210-0002 | B2: Chenguetai Quichine | C2: 862441603 | D2: Felizardo Constantino Chicoche | E2: 861948841 | F2: Manica | G2: Barue | H2: Chuala | I2: Kit 1 | J2: 0 | K2: 13 | L2: 13
A3: 0210-0003 | B3: Daniel J.F.Paulo | C3: 863413681 | D3: Felizardo Constantino Chicoche | E3: 861948841 | F3: Manica | G3: Barue | H3: Nhabuto | I3: Kit 1 | J3: 0 | K3: 14 | L3: 14
A4: 0210-0004 | B4: Francisca C. Roia | C4: 861570229 | D4: Felizardo Constantino Chicoche | E4: 861948841 | F4: Manica | G4: Barue | H4: Nfudze | I4: Kit 1 | J4: 0 | K4: 8 | L4: 8
A5: 0210-0005 | B5: Gimmy Cliffy Narcisio | C5: 847244778 | D5: Felizardo Constantino Chicoche | E5: 861948841 | F5: Manica | G5: Barue | H5: Inhazonia | I5: Kit 1 | J5: 0 | K5: 13 | L5: 13
A6: 0210-0006 | B6: Isabel Luis Mario | C6: 873392617 | D6: Felizardo Constantino Chicoche | E6: 861948841 | F6: Manica | G6: Barue | H6: Inhazonia | I6: Kit 1 | J6: 0 | K6: 19 | L6: 19
A7: 0210-0007 | B7: Joaquim José Simão | C7: 860289921 | D7: Felizardo Constantino Chicoche | E7: 861948841 | F7: Manica | G7: Barue | H7: Chuala | I7: Kit 1 | J7: 0 | K7: 18 | L7: 18
A8: 0210-0008 | B8: Joelmo Francisco | C8: 872763746 | D8: Felizardo Constantino Chicoche | E8: 861948841 | F8: Manica | G8: Barue | H8: Catandica | I8: Kit 1 | J8: 0 | K8: 32 | L8: 32
A9: 0210-0009 | B9: Lucas Jose Mussosso | C9: 865082456 | D9: Felizardo Constantino Chicoche | E9: 861948841 | F9: Manica | G9: Barue | H9: Honde sede | I9: Kit 1 | J9: 0 | K9: 12 | L9: 12
A10: 0210-0010 | B10: Mugabe G. Monteiro | C10: 878727342 | D10: Felizardo Constantino Chicoche | E10: 861948841 | F10: Manica | G10: Barue | H10: Chuala | I10: Kit 1 | J10: 0 | K10: 13 | L10: 13
A11: 0210-0011 | B11: Rui Banqueiro | C11: 846867468 | D11: Felizardo Constantino Chicoche | E11: 861948841 | F11: Manica | G11: Barue | H11: Chuala | I11: Kit 1 | J11: 0 | K11: 11 | L11: 11
A12: 0210-0012 | B12: Tomas Samuel Lázaro | C12: 842696591 | D12: Felizardo Constantino Chicoche | E12: 861948841 | F12: Manica | G12: Barue | H12: Nhassacara | I12: Kit 1 | J12: 0 | K12: 13 | L12: 13
A13: 0211-0002 | B13: Aminosse Lucas licosso | C13: 845490249 | D13: Esmael Gonsalvez Pinto | E13: 878173978 | F13: Manica | G13: Machaze | H13: Sambassoca | I13: Kit 1 | J13: 0 | K13: 1 | L13: 1
... A105: 0510-0007 | B105: Terio Fevereiro Semente | C105: 862409932 | D105: Jerson Francisco Saguate | E105: 873584824 | F105: Tete | G105: Chifunde | H105: Nsadzu Sede | I105: Kit 1 | J105: 0 | K105: 11 | L105: 11
A106: 0511-0001 | B106: Bonifácio Frederico Maferano | C106: 857018425 | D106: Rosa Chioi | E106: 822202505 | F106: Tete | G106: Cidade de Tete | I106: Kit 1 | J106: 0 | K106: 96 | L106: 96
A107: 0511-0002 | B107: Cláudio Francisco Presente | C107: 848021417 | D107: Rosa Chioi | E107: 822202505 | F107: Tete | G107: Cidade de Tete | I107: Kit 1 | J107: 0 | K107: 47 | L107: 47
A108: 0511-0003 | B108: Dudú Januário Júlio | C108: 844747713 | D108: Rosa Chioi | E108: 822202505 | F108: Tete | G108: Cidade de Tete | I108: Kit 1 | J108: 0 | K108: 47 | L108: 47
A109: 0511-0004 | B109: Inês Vasco Balanca | C109: 873189788 | D109: Rosa Chioi | E109: 822202505 | F109: Tete | G109: Cidade de Tete | I109: Kit 1 | J109: 0 | K109: 47 | L109: 47
A110: 0511-0005 | B110: Lia Manuel Mapolissa | C110: 847321638 | D110: Rosa Chioi | E110: 822202505 | F110: Tete | G110: Cidade de Tete | I110: Kit 1 | J110: 0 | K110: 48 | L110: 48
A111: 0511-0006 | B111: Rosa Chioi | C111: 822202505 | D111: Rosa Chioi | E111: 822202505 | F111: Tete | G111: Cidade de Tete | I111: Kit 1 | J111: 0 | K111: 15 | L111: 15
A112: 0504-0005 | B112: Adelia Eduardo | C112: 867346208 | D112: Ester Domingos Reis | E112: 866993712 | F112: Tete | G112: Doa | H112: Chueza | I112: Kit 1 | J112: 0 | K112: 77 | L112: 77
A113: 0504-0006 | B113: Almirante Augusto | C113: 867246140 | D113: Ester Domingos Reis | E113: 866993712 | F113: Tete | G113: Doa | H113: Salima | I113: Kit 1 | J113: 0 | K113: 55 | L113: 55
A114: 0504-0007 | B114: Anita Domingos | C114: 8634495223 | D114: Ester Domingos Reis | E114: 866993712 | F114: Tete | G114: Doa | H114: Salima | I114: Kit 1 | J114: 0 | K114: 40 | L114: 40
A115: 0504-0008 | B115: Gervasio Rodrigues | C115: 873901527 | D115: Ester Domingos Reis | E115: 866993712 | F115: Tete | G115: Doa | H115: Doa-Sede | I115: Kit 1 | J115: 0 | K115: 35 | L115: 35
A116: 0512-0001 | B116: Anita António Felisberto João | C116: 877961829 | D116: Juma Pedro Simital | E116: 862155221 | F116: Tete | G116: Macanga | H116: Namadende | I116: Kit 1 | J116: 0 | K116: 5 | L116: 5
A117: 0512-0002 | B117: Elsa Stella António | C117: 840501282 | D117: Juma Pedro Simital | E117: 862155221 | F117: Tete | G117: Macanga | H117: Furancungo | I117: Kit 1 | J117: 0 | K117: 19 | L117: 19
A118: 0512-0003 | B118: Faustino Inácio Almoço João | C118: 860555303 | D118: Juma Pedro Simital | E118: 862155221 | F118: Tete | G118: Macanga | H118: Furancungo | I118: Kit 1 | J118: 0 | K118: 3 | L118: 3
A119: 0512-0004 | B119: Quito Albino Sande | C119: 864694802 | D119: Juma Pedro Simital | E119: 862155221 | F119: Tete | G119: Macanga | H119: Báuè | I119: Kit 1 | J119: 0 | K119: 1 | L119: 1
A120: 0512-0005 | B120: Tania Francisco | C120: 879221061 | D120: Juma Pedro Simital | E120: 862155221 | F120: Tete | G120: Macanga | H120: Gandali | I120: Kit 1 | J120: 0 | K120: 5 | L120: 5
A121: 0512-0006 | B121: Titos Francisco Tomas | C121: 879959161 | D121: Juma Pedro Simital | E121: 862155221 | F121: Tete | G121: Macanga | H121: Gandali | I121: Kit 1 | J121: 0 | K121: 3 | L121: 3
A122: 0512-0007 | B122: Verónica Geremias Mateus Ramucesse | C122: 876298744 | D122: Juma Pedro Simital | E122: 862155221 | F122: Tete | G122: Macanga | H122: Campala | I122: Kit 1 | J122: 0 | K122: 5 | L122: 5
A123: 0512-0008 | B123: Wilson Lucas Petroce | C123: 863026920 | D123: Juma Pedro Simital | E123: 862155221 | F123: Tete | G123: Macanga | H123: Campala | I123: Kit 1 | J123: 0 | K123: 9 | L123: 9
... A135: 0506-0005 | B135: Herminio Vasco | C135: 878814519 | D135: Bernardo Xavier Jojo | E135: 865438512 | F135: Tete | G135: Moatize | H135: Mpandzu | I135: Kit 1 | J135: 0 | K135: 100 | L135: 100
B136: Sem nome 1 | D136: Bernardo Xavier Jojo | E136: 865438512 | F136: Tete | G136: Moatize | H136: Ntsungo | I136: Kit 1 | J136: 0 | K136: 1 | L136: 1
B137: Sem nome 4 | F137: Tete | G137: Moatize | H137: Macuane Mangol | I137: Kit 1 | J137: 0 | K137: 99 | L137: 99
A138: 0506-0002 | B138: Tomás Jorge António Váz | C138: 865514026 | D138: Bernardo Xavier Jojo | E138: 865438512 | F138: Tete | G138: Moatize | I138: Kit 1 | J138: 464 | K138: 0 | L138: -464
A139: 0514-0001 | B139: Antonio Osvaldo Ausse | D139: Toto Araujo Macajo | E139: 846916018 | F139: Tete | G139: Mutarara | H139: Canhungue | I139: Kit 1 | J139: 0 | K139: 56 | L139: 56
A140: 0514-0002 | B140: Carlito Jose Angola | C140: 841484730 | D140: Toto Araujo Macajo | E140: 846916018 | F140: Tete | G140: Mutarara | H140: Vila Nova da Fronteira | I140: Kit 1 | J140: 0 | K140: 56 | L140: 56
A141: 0514-0003 | B141: Isaquel Amilcar Andate-Fanessi | D141: Toto Araujo Macajo | E141: 846916018 | F141: Tete | G141: Mutarara | H141: Inhangoma-Sede | I141: Kit 1 | J141: 0 | K141: 56 | L141: 56
A142: 0514-0004 | B142: Julio Vasco Chimica | C142: 840200222 | D142: Toto Araujo Macajo | E142: 846916018 | F142: Tete | G142: Mutarara | H142: Nhamayabwe-Sede | I142: Kit 1 | J142: 0 | K142: 56 | L142: 56
...

Sheet Composição dos Kits
A1: Composição dos Kits de Emergência
A3: Insumo | B3: Unidade | C3: Kit 1 (por família) | D3: Kit 2 (por família) | E3: Observação
A4: Milho | B4: Kg | C4: 12.5 | D4: 0 | E4: Apenas no Kit 1
A5: Arroz | B5: Kg | C5: 0 | D5: 50 | E5: Apenas no Kit 2
A6: Feijão Vulgar | B6: Kg | C6: 15 | D6: 15 | E6: Presente em ambos
A7: Couve | B7: g | C7: 10 | D7: 10 | E7: Sementes
A8: Alface | B8: g | C8: 10 | D8: 10 | E8: Sementes
A9: NPK 12.24.12 | B9: Kg | C9: 50 | D9: 50 | E9: Fertilizante
A10: Enxada | B10: un | C10: 1 | D10: 1 | E10: Ferramenta
A11: Emamectim Benzoato | B11: L | C11: 0.5 | D11: 0.5 | E11: Insecticida (ambos)
A12: Imidacloprid | B12: L | C12: 0.5 | D12: 0 | E12: Apenas no Kit 1
A13: MCPA | B13: L | C13: 0 | D13: 1.5 | E13: Apenas no Kit 2 (herbicida)
